2020-12-14 15:04:11.341 | ERROR    | fate_test.scripts._utils:_upload_data:123 - exception id: 91373ebc-3dda-11eb-997d-5254009c6d10
Traceback (most recent call last):

  File "/data/projects/standalone-fate-master-1.5.0/python/wjc/venv/lib/python3.6/site-packages/fate_test/_flow_client.py", line 45, in upload_data
    response, data_path = self._upload_data(conf=data.config, verbose=0, drop=1)
                          │    │                 │    └ {'head': 1, 'partition': 4, 'table_name': 'breast_hetero_guest', 'namespace': 'experiment', 'file': '/data/projects/standalon...
                          │    │                 └ <fate_test._parser.Data object at 0x7f8c4e1d95f8>
                          │    └ <function FLOWClient._upload_data at 0x7f8c78db3840>
                          └ <fate_test._flow_client.FLOWClient object at 0x7f8c79acd240>
  File "/data/projects/standalone-fate-master-1.5.0/python/wjc/venv/lib/python3.6/site-packages/fate_test/_flow_client.py", line 120, in _upload_data
    verbose=verbose, drop=drop)
            │             └ 1
            └ 0
  File "/data/projects/standalone-fate-master-1.5.0/python/wjc/venv/lib/python3.6/site-packages/fate_test/_flow_client.py", line 195, in flow_client
    'retmsg': "Internal server error. Nothing in response. You may check out the configuration in "

ValueError: {'retcode': 100, 'retmsg': "Internal server error. Nothing in response. You may check out the configuration in 'FATE/conf/server_conf.yaml' and restart fate flow server."}


The above exception was the direct cause of the following exception:


Traceback (most recent call last):

  File "/data/projects/standalone-fate-master-1.5.0/python/wjc/venv/bin/fate_test", line 8, in <module>
    sys.exit(cli())
    │   │    └ <MultiCLI cli>
    │   └ <built-in function exit>
    └ <module 'sys' (built-in)>
  File "/data/projects/standalone-fate-master-1.5.0/python/wjc/venv/lib/python3.6/site-packages/click/core.py", line 829, in __call__
    return self.main(*args, **kwargs)
           │    │     │       └ {}
           │    │     └ ()
           │    └ <function BaseCommand.main at 0x7f8c7ecf3d90>
           └ <MultiCLI cli>
  File "/data/projects/standalone-fate-master-1.5.0/python/wjc/venv/lib/python3.6/site-packages/click/core.py", line 782, in main
    rv = self.invoke(ctx)
         │    │      └ <click.core.Context object at 0x7f8c7f2d0f98>
         │    └ <function MultiCommand.invoke at 0x7f8c7ef6eae8>
         └ <MultiCLI cli>
  File "/data/projects/standalone-fate-master-1.5.0/python/wjc/venv/lib/python3.6/site-packages/click/core.py", line 1259, in invoke
    return _process_result(sub_ctx.command.invoke(sub_ctx))
           │               │       │       │      └ <click.core.Context object at 0x7f8c7f2c1cf8>
           │               │       │       └ <function Command.invoke at 0x7f8c7ef6e730>
           │               │       └ <Command suite>
           │               └ <click.core.Context object at 0x7f8c7f2c1cf8>
           └ <function MultiCommand.invoke.<locals>._process_result at 0x7f8c7f2c0400>
  File "/data/projects/standalone-fate-master-1.5.0/python/wjc/venv/lib/python3.6/site-packages/click/core.py", line 1066, in invoke
    return ctx.invoke(self.callback, **ctx.params)
           │   │      │    │           │   └ {'include': ('../../examples/experiment_template/dsl/v2/hetero_secureboost/hetero_sbt_testsuite.json',), 'exclude': (), 'repl...
           │   │      │    │           └ <click.core.Context object at 0x7f8c7f2c1cf8>
           │   │      │    └ <function run_suite at 0x7f8c4e2478c8>
           │   │      └ <Command suite>
           │   └ <function Context.invoke at 0x7f8c7ef71d90>
           └ <click.core.Context object at 0x7f8c7f2c1cf8>
  File "/data/projects/standalone-fate-master-1.5.0/python/wjc/venv/lib/python3.6/site-packages/click/core.py", line 610, in invoke
    return callback(*args, **kwargs)
           │         │       └ {'include': ('../../examples/experiment_template/dsl/v2/hetero_secureboost/hetero_sbt_testsuite.json',), 'exclude': (), 'repl...
           │         └ ()
           └ <function run_suite at 0x7f8c4e2478c8>
  File "/data/projects/standalone-fate-master-1.5.0/python/wjc/venv/lib/python3.6/site-packages/click/decorators.py", line 21, in new_func
    return f(get_current_context(), *args, **kwargs)
           │ │                       │       └ {'include': ('../../examples/experiment_template/dsl/v2/hetero_secureboost/hetero_sbt_testsuite.json',), 'exclude': (), 'repl...
           │ │                       └ ()
           │ └ <function get_current_context at 0x7f8c7ef78488>
           └ <function run_suite at 0x7f8c4e247840>
  File "/data/projects/standalone-fate-master-1.5.0/python/wjc/venv/lib/python3.6/site-packages/fate_test/scripts/testsuite_cli.py", line 89, in run_suite
    _upload_data(client, suite, config_inst)
    │            │       │      └ <fate_test._config.Config object at 0x7f8c86a5b9b0>
    │            │       └ <fate_test._parser.Testsuite object at 0x7f8c4e1b3dd8>
    │            └ <fate_test._client.Clients object at 0x7f8c86a91630>
    └ <function _upload_data at 0x7f8c4e2338c8>
> File "/data/projects/standalone-fate-master-1.5.0/python/wjc/venv/lib/python3.6/site-packages/fate_test/scripts/_utils.py", line 113, in _upload_data
    response, data_path = clients[data.role_str].upload_data(data, _call_back)
                          │       │    │                     │     └ <function _upload_data.<locals>._call_back at 0x7f8c4e1d1488>
                          │       │    │                     └ <fate_test._parser.Data object at 0x7f8c4e1d95f8>
                          │       │    └ 'guest_0'
                          │       └ <fate_test._parser.Data object at 0x7f8c4e1d95f8>
                          └ <fate_test._client.Clients object at 0x7f8c86a91630>
  File "/data/projects/standalone-fate-master-1.5.0/python/wjc/venv/lib/python3.6/site-packages/fate_test/_flow_client.py", line 51, in upload_data
    raise RuntimeError(f"upload data failed") from e

RuntimeError: upload data failed
2020-12-14 15:04:11.353 | ERROR    | fate_test.scripts._utils:_upload_data:123 - exception id: 913908dc-3dda-11eb-997d-5254009c6d10
Traceback (most recent call last):

  File "/data/projects/standalone-fate-master-1.5.0/python/wjc/venv/lib/python3.6/site-packages/fate_test/_flow_client.py", line 45, in upload_data
    response, data_path = self._upload_data(conf=data.config, verbose=0, drop=1)
                          │    │                 │    └ {'head': 1, 'partition': 4, 'table_name': 'breast_hetero_host_tag_value', 'namespace': 'experiment', 'file': '/data/projects/...
                          │    │                 └ <fate_test._parser.Data object at 0x7f8c4e1d9588>
                          │    └ <function FLOWClient._upload_data at 0x7f8c78db3840>
                          └ <fate_test._flow_client.FLOWClient object at 0x7f8c79acd240>
  File "/data/projects/standalone-fate-master-1.5.0/python/wjc/venv/lib/python3.6/site-packages/fate_test/_flow_client.py", line 120, in _upload_data
    verbose=verbose, drop=drop)
            │             └ 1
            └ 0
  File "/data/projects/standalone-fate-master-1.5.0/python/wjc/venv/lib/python3.6/site-packages/fate_test/_flow_client.py", line 195, in flow_client
    'retmsg': "Internal server error. Nothing in response. You may check out the configuration in "

ValueError: {'retcode': 100, 'retmsg': "Internal server error. Nothing in response. You may check out the configuration in 'FATE/conf/server_conf.yaml' and restart fate flow server."}


The above exception was the direct cause of the following exception:


Traceback (most recent call last):

  File "/data/projects/standalone-fate-master-1.5.0/python/wjc/venv/bin/fate_test", line 8, in <module>
    sys.exit(cli())
    │   │    └ <MultiCLI cli>
    │   └ <built-in function exit>
    └ <module 'sys' (built-in)>
  File "/data/projects/standalone-fate-master-1.5.0/python/wjc/venv/lib/python3.6/site-packages/click/core.py", line 829, in __call__
    return self.main(*args, **kwargs)
           │    │     │       └ {}
           │    │     └ ()
           │    └ <function BaseCommand.main at 0x7f8c7ecf3d90>
           └ <MultiCLI cli>
  File "/data/projects/standalone-fate-master-1.5.0/python/wjc/venv/lib/python3.6/site-packages/click/core.py", line 782, in main
    rv = self.invoke(ctx)
         │    │      └ <click.core.Context object at 0x7f8c7f2d0f98>
         │    └ <function MultiCommand.invoke at 0x7f8c7ef6eae8>
         └ <MultiCLI cli>
  File "/data/projects/standalone-fate-master-1.5.0/python/wjc/venv/lib/python3.6/site-packages/click/core.py", line 1259, in invoke
    return _process_result(sub_ctx.command.invoke(sub_ctx))
           │               │       │       │      └ <click.core.Context object at 0x7f8c7f2c1cf8>
           │               │       │       └ <function Command.invoke at 0x7f8c7ef6e730>
           │               │       └ <Command suite>
           │               └ <click.core.Context object at 0x7f8c7f2c1cf8>
           └ <function MultiCommand.invoke.<locals>._process_result at 0x7f8c7f2c0400>
  File "/data/projects/standalone-fate-master-1.5.0/python/wjc/venv/lib/python3.6/site-packages/click/core.py", line 1066, in invoke
    return ctx.invoke(self.callback, **ctx.params)
           │   │      │    │           │   └ {'include': ('../../examples/experiment_template/dsl/v2/hetero_secureboost/hetero_sbt_testsuite.json',), 'exclude': (), 'repl...
           │   │      │    │           └ <click.core.Context object at 0x7f8c7f2c1cf8>
           │   │      │    └ <function run_suite at 0x7f8c4e2478c8>
           │   │      └ <Command suite>
           │   └ <function Context.invoke at 0x7f8c7ef71d90>
           └ <click.core.Context object at 0x7f8c7f2c1cf8>
  File "/data/projects/standalone-fate-master-1.5.0/python/wjc/venv/lib/python3.6/site-packages/click/core.py", line 610, in invoke
    return callback(*args, **kwargs)
           │         │       └ {'include': ('../../examples/experiment_template/dsl/v2/hetero_secureboost/hetero_sbt_testsuite.json',), 'exclude': (), 'repl...
           │         └ ()
           └ <function run_suite at 0x7f8c4e2478c8>
  File "/data/projects/standalone-fate-master-1.5.0/python/wjc/venv/lib/python3.6/site-packages/click/decorators.py", line 21, in new_func
    return f(get_current_context(), *args, **kwargs)
           │ │                       │       └ {'include': ('../../examples/experiment_template/dsl/v2/hetero_secureboost/hetero_sbt_testsuite.json',), 'exclude': (), 'repl...
           │ │                       └ ()
           │ └ <function get_current_context at 0x7f8c7ef78488>
           └ <function run_suite at 0x7f8c4e247840>
  File "/data/projects/standalone-fate-master-1.5.0/python/wjc/venv/lib/python3.6/site-packages/fate_test/scripts/testsuite_cli.py", line 89, in run_suite
    _upload_data(client, suite, config_inst)
    │            │       │      └ <fate_test._config.Config object at 0x7f8c86a5b9b0>
    │            │       └ <fate_test._parser.Testsuite object at 0x7f8c4e1b3dd8>
    │            └ <fate_test._client.Clients object at 0x7f8c86a91630>
    └ <function _upload_data at 0x7f8c4e2338c8>
> File "/data/projects/standalone-fate-master-1.5.0/python/wjc/venv/lib/python3.6/site-packages/fate_test/scripts/_utils.py", line 113, in _upload_data
    response, data_path = clients[data.role_str].upload_data(data, _call_back)
                          │       │    │                     │     └ <function _upload_data.<locals>._call_back at 0x7f8c4e137d90>
                          │       │    │                     └ <fate_test._parser.Data object at 0x7f8c4e1d9588>
                          │       │    └ 'host_0'
                          │       └ <fate_test._parser.Data object at 0x7f8c4e1d9588>
                          └ <fate_test._client.Clients object at 0x7f8c86a91630>
  File "/data/projects/standalone-fate-master-1.5.0/python/wjc/venv/lib/python3.6/site-packages/fate_test/_flow_client.py", line 51, in upload_data
    raise RuntimeError(f"upload data failed") from e

RuntimeError: upload data failed
2020-12-14 15:04:11.358 | ERROR    | fate_test.scripts._utils:_upload_data:123 - exception id: 9139d4b0-3dda-11eb-997d-5254009c6d10
Traceback (most recent call last):

  File "/data/projects/standalone-fate-master-1.5.0/python/wjc/venv/lib/python3.6/site-packages/fate_test/_flow_client.py", line 45, in upload_data
    response, data_path = self._upload_data(conf=data.config, verbose=0, drop=1)
                          │    │                 │    └ {'head': 1, 'partition': 4, 'table_name': 'mock_tag_hetero_host', 'namespace': 'experiment', 'file': '/data/projects/standalo...
                          │    │                 └ <fate_test._parser.Data object at 0x7f8c4e1d9710>
                          │    └ <function FLOWClient._upload_data at 0x7f8c78db3840>
                          └ <fate_test._flow_client.FLOWClient object at 0x7f8c79acd240>
  File "/data/projects/standalone-fate-master-1.5.0/python/wjc/venv/lib/python3.6/site-packages/fate_test/_flow_client.py", line 120, in _upload_data
    verbose=verbose, drop=drop)
            │             └ 1
            └ 0
  File "/data/projects/standalone-fate-master-1.5.0/python/wjc/venv/lib/python3.6/site-packages/fate_test/_flow_client.py", line 195, in flow_client
    'retmsg': "Internal server error. Nothing in response. You may check out the configuration in "

ValueError: {'retcode': 100, 'retmsg': "Internal server error. Nothing in response. You may check out the configuration in 'FATE/conf/server_conf.yaml' and restart fate flow server."}


The above exception was the direct cause of the following exception:


Traceback (most recent call last):

  File "/data/projects/standalone-fate-master-1.5.0/python/wjc/venv/bin/fate_test", line 8, in <module>
    sys.exit(cli())
    │   │    └ <MultiCLI cli>
    │   └ <built-in function exit>
    └ <module 'sys' (built-in)>
  File "/data/projects/standalone-fate-master-1.5.0/python/wjc/venv/lib/python3.6/site-packages/click/core.py", line 829, in __call__
    return self.main(*args, **kwargs)
           │    │     │       └ {}
           │    │     └ ()
           │    └ <function BaseCommand.main at 0x7f8c7ecf3d90>
           └ <MultiCLI cli>
  File "/data/projects/standalone-fate-master-1.5.0/python/wjc/venv/lib/python3.6/site-packages/click/core.py", line 782, in main
    rv = self.invoke(ctx)
         │    │      └ <click.core.Context object at 0x7f8c7f2d0f98>
         │    └ <function MultiCommand.invoke at 0x7f8c7ef6eae8>
         └ <MultiCLI cli>
  File "/data/projects/standalone-fate-master-1.5.0/python/wjc/venv/lib/python3.6/site-packages/click/core.py", line 1259, in invoke
    return _process_result(sub_ctx.command.invoke(sub_ctx))
           │               │       │       │      └ <click.core.Context object at 0x7f8c7f2c1cf8>
           │               │       │       └ <function Command.invoke at 0x7f8c7ef6e730>
           │               │       └ <Command suite>
           │               └ <click.core.Context object at 0x7f8c7f2c1cf8>
           └ <function MultiCommand.invoke.<locals>._process_result at 0x7f8c7f2c0400>
  File "/data/projects/standalone-fate-master-1.5.0/python/wjc/venv/lib/python3.6/site-packages/click/core.py", line 1066, in invoke
    return ctx.invoke(self.callback, **ctx.params)
           │   │      │    │           │   └ {'include': ('../../examples/experiment_template/dsl/v2/hetero_secureboost/hetero_sbt_testsuite.json',), 'exclude': (), 'repl...
           │   │      │    │           └ <click.core.Context object at 0x7f8c7f2c1cf8>
           │   │      │    └ <function run_suite at 0x7f8c4e2478c8>
           │   │      └ <Command suite>
           │   └ <function Context.invoke at 0x7f8c7ef71d90>
           └ <click.core.Context object at 0x7f8c7f2c1cf8>
  File "/data/projects/standalone-fate-master-1.5.0/python/wjc/venv/lib/python3.6/site-packages/click/core.py", line 610, in invoke
    return callback(*args, **kwargs)
           │         │       └ {'include': ('../../examples/experiment_template/dsl/v2/hetero_secureboost/hetero_sbt_testsuite.json',), 'exclude': (), 'repl...
           │         └ ()
           └ <function run_suite at 0x7f8c4e2478c8>
  File "/data/projects/standalone-fate-master-1.5.0/python/wjc/venv/lib/python3.6/site-packages/click/decorators.py", line 21, in new_func
    return f(get_current_context(), *args, **kwargs)
           │ │                       │       └ {'include': ('../../examples/experiment_template/dsl/v2/hetero_secureboost/hetero_sbt_testsuite.json',), 'exclude': (), 'repl...
           │ │                       └ ()
           │ └ <function get_current_context at 0x7f8c7ef78488>
           └ <function run_suite at 0x7f8c4e247840>
  File "/data/projects/standalone-fate-master-1.5.0/python/wjc/venv/lib/python3.6/site-packages/fate_test/scripts/testsuite_cli.py", line 89, in run_suite
    _upload_data(client, suite, config_inst)
    │            │       │      └ <fate_test._config.Config object at 0x7f8c86a5b9b0>
    │            │       └ <fate_test._parser.Testsuite object at 0x7f8c4e1b3dd8>
    │            └ <fate_test._client.Clients object at 0x7f8c86a91630>
    └ <function _upload_data at 0x7f8c4e2338c8>
> File "/data/projects/standalone-fate-master-1.5.0/python/wjc/venv/lib/python3.6/site-packages/fate_test/scripts/_utils.py", line 113, in _upload_data
    response, data_path = clients[data.role_str].upload_data(data, _call_back)
                          │       │    │                     │     └ <function _upload_data.<locals>._call_back at 0x7f8c4e0b2950>
                          │       │    │                     └ <fate_test._parser.Data object at 0x7f8c4e1d9710>
                          │       │    └ 'host_0'
                          │       └ <fate_test._parser.Data object at 0x7f8c4e1d9710>
                          └ <fate_test._client.Clients object at 0x7f8c86a91630>
  File "/data/projects/standalone-fate-master-1.5.0/python/wjc/venv/lib/python3.6/site-packages/fate_test/_flow_client.py", line 51, in upload_data
    raise RuntimeError(f"upload data failed") from e

RuntimeError: upload data failed
2020-12-14 15:04:11.465 | ERROR    | fate_test.scripts.testsuite_cli:_raise:142 - exception id: 914a197e-3dda-11eb-997d-5254009c6d10
Traceback (most recent call last):

  File "/data/projects/standalone-fate-master-1.5.0/python/wjc/venv/lib/python3.6/site-packages/fate_test/_flow_client.py", line 62, in submit_job
    response = self._submit_job(**job.submit_params)
               │    │             │   └ <property object at 0x7f8c7b5c4458>
               │    │             └ <fate_test._parser.Job object at 0x7f8c4e1d96d8>
               │    └ <function FLOWClient._submit_job at 0x7f8c78db3950>
               └ <fate_test._flow_client.FLOWClient object at 0x7f8c79acd240>
  File "/data/projects/standalone-fate-master-1.5.0/python/wjc/venv/lib/python3.6/site-packages/fate_test/_flow_client.py", line 137, in _submit_job
    response = SubmitJobResponse(self.flow_client(request='job/submit', param=param))
               │                 │    │                                       └ {'job_dsl': '/data/projects/standalone-fate-master-1.5.0/python/fate_test/cache/submit_dsl.json', 'job_runtime_conf': '/data/...
               │                 │    └ <function FLOWClient.flow_client at 0x7f8c78db3bf8>
               │                 └ <fate_test._flow_client.FLOWClient object at 0x7f8c79acd240>
               └ <class 'fate_test._flow_client.SubmitJobResponse'>
  File "/data/projects/standalone-fate-master-1.5.0/python/wjc/venv/lib/python3.6/site-packages/fate_test/_flow_client.py", line 195, in flow_client
    'retmsg': "Internal server error. Nothing in response. You may check out the configuration in "

ValueError: {'retcode': 100, 'retmsg': "Internal server error. Nothing in response. You may check out the configuration in 'FATE/conf/server_conf.yaml' and restart fate flow server."}


The above exception was the direct cause of the following exception:


Traceback (most recent call last):

  File "/data/projects/standalone-fate-master-1.5.0/python/wjc/venv/bin/fate_test", line 8, in <module>
    sys.exit(cli())
    │   │    └ <MultiCLI cli>
    │   └ <built-in function exit>
    └ <module 'sys' (built-in)>
  File "/data/projects/standalone-fate-master-1.5.0/python/wjc/venv/lib/python3.6/site-packages/click/core.py", line 829, in __call__
    return self.main(*args, **kwargs)
           │    │     │       └ {}
           │    │     └ ()
           │    └ <function BaseCommand.main at 0x7f8c7ecf3d90>
           └ <MultiCLI cli>
  File "/data/projects/standalone-fate-master-1.5.0/python/wjc/venv/lib/python3.6/site-packages/click/core.py", line 782, in main
    rv = self.invoke(ctx)
         │    │      └ <click.core.Context object at 0x7f8c7f2d0f98>
         │    └ <function MultiCommand.invoke at 0x7f8c7ef6eae8>
         └ <MultiCLI cli>
  File "/data/projects/standalone-fate-master-1.5.0/python/wjc/venv/lib/python3.6/site-packages/click/core.py", line 1259, in invoke
    return _process_result(sub_ctx.command.invoke(sub_ctx))
           │               │       │       │      └ <click.core.Context object at 0x7f8c7f2c1cf8>
           │               │       │       └ <function Command.invoke at 0x7f8c7ef6e730>
           │               │       └ <Command suite>
           │               └ <click.core.Context object at 0x7f8c7f2c1cf8>
           └ <function MultiCommand.invoke.<locals>._process_result at 0x7f8c7f2c0400>
  File "/data/projects/standalone-fate-master-1.5.0/python/wjc/venv/lib/python3.6/site-packages/click/core.py", line 1066, in invoke
    return ctx.invoke(self.callback, **ctx.params)
           │   │      │    │           │   └ {'include': ('../../examples/experiment_template/dsl/v2/hetero_secureboost/hetero_sbt_testsuite.json',), 'exclude': (), 'repl...
           │   │      │    │           └ <click.core.Context object at 0x7f8c7f2c1cf8>
           │   │      │    └ <function run_suite at 0x7f8c4e2478c8>
           │   │      └ <Command suite>
           │   └ <function Context.invoke at 0x7f8c7ef71d90>
           └ <click.core.Context object at 0x7f8c7f2c1cf8>
  File "/data/projects/standalone-fate-master-1.5.0/python/wjc/venv/lib/python3.6/site-packages/click/core.py", line 610, in invoke
    return callback(*args, **kwargs)
           │         │       └ {'include': ('../../examples/experiment_template/dsl/v2/hetero_secureboost/hetero_sbt_testsuite.json',), 'exclude': (), 'repl...
           │         └ ()
           └ <function run_suite at 0x7f8c4e2478c8>
  File "/data/projects/standalone-fate-master-1.5.0/python/wjc/venv/lib/python3.6/site-packages/click/decorators.py", line 21, in new_func
    return f(get_current_context(), *args, **kwargs)
           │ │                       │       └ {'include': ('../../examples/experiment_template/dsl/v2/hetero_secureboost/hetero_sbt_testsuite.json',), 'exclude': (), 'repl...
           │ │                       └ ()
           │ └ <function get_current_context at 0x7f8c7ef78488>
           └ <function run_suite at 0x7f8c4e247840>
  File "/data/projects/standalone-fate-master-1.5.0/python/wjc/venv/lib/python3.6/site-packages/fate_test/scripts/testsuite_cli.py", line 99, in run_suite
    update_component_parameters)
    └ {}
> File "/data/projects/standalone-fate-master-1.5.0/python/wjc/venv/lib/python3.6/site-packages/fate_test/scripts/testsuite_cli.py", line 172, in _submit_job
    response = clients["guest_0"].submit_job(job=job, callback=_call_back)
               │                                 │             └ <function _submit_job.<locals>._call_back at 0x7f8c4e0c4620>
               │                                 └ <fate_test._parser.Job object at 0x7f8c4e1d96d8>
               └ <fate_test._client.Clients object at 0x7f8c86a91630>
  File "/data/projects/standalone-fate-master-1.5.0/python/wjc/venv/lib/python3.6/site-packages/fate_test/_flow_client.py", line 69, in submit_job
    raise RuntimeError(f"submit job failed") from e

RuntimeError: submit job failed
2020-12-14 15:04:11.671 | ERROR    | fate_test.scripts.testsuite_cli:_raise:142 - exception id: 91699cfe-3dda-11eb-997d-5254009c6d10
Traceback (most recent call last):

  File "/data/projects/standalone-fate-master-1.5.0/python/wjc/venv/lib/python3.6/site-packages/fate_test/_flow_client.py", line 62, in submit_job
    response = self._submit_job(**job.submit_params)
               │    │             │   └ <property object at 0x7f8c7b5c4458>
               │    │             └ <fate_test._parser.Job object at 0x7f8c4e20fd30>
               │    └ <function FLOWClient._submit_job at 0x7f8c78db3950>
               └ <fate_test._flow_client.FLOWClient object at 0x7f8c79acd240>
  File "/data/projects/standalone-fate-master-1.5.0/python/wjc/venv/lib/python3.6/site-packages/fate_test/_flow_client.py", line 137, in _submit_job
    response = SubmitJobResponse(self.flow_client(request='job/submit', param=param))
               │                 │    │                                       └ {'job_dsl': '/data/projects/standalone-fate-master-1.5.0/python/fate_test/cache/submit_dsl.json', 'job_runtime_conf': '/data/...
               │                 │    └ <function FLOWClient.flow_client at 0x7f8c78db3bf8>
               │                 └ <fate_test._flow_client.FLOWClient object at 0x7f8c79acd240>
               └ <class 'fate_test._flow_client.SubmitJobResponse'>
  File "/data/projects/standalone-fate-master-1.5.0/python/wjc/venv/lib/python3.6/site-packages/fate_test/_flow_client.py", line 195, in flow_client
    'retmsg': "Internal server error. Nothing in response. You may check out the configuration in "

ValueError: {'retcode': 100, 'retmsg': "Internal server error. Nothing in response. You may check out the configuration in 'FATE/conf/server_conf.yaml' and restart fate flow server."}


The above exception was the direct cause of the following exception:


Traceback (most recent call last):

  File "/data/projects/standalone-fate-master-1.5.0/python/wjc/venv/bin/fate_test", line 8, in <module>
    sys.exit(cli())
    │   │    └ <MultiCLI cli>
    │   └ <built-in function exit>
    └ <module 'sys' (built-in)>
  File "/data/projects/standalone-fate-master-1.5.0/python/wjc/venv/lib/python3.6/site-packages/click/core.py", line 829, in __call__
    return self.main(*args, **kwargs)
           │    │     │       └ {}
           │    │     └ ()
           │    └ <function BaseCommand.main at 0x7f8c7ecf3d90>
           └ <MultiCLI cli>
  File "/data/projects/standalone-fate-master-1.5.0/python/wjc/venv/lib/python3.6/site-packages/click/core.py", line 782, in main
    rv = self.invoke(ctx)
         │    │      └ <click.core.Context object at 0x7f8c7f2d0f98>
         │    └ <function MultiCommand.invoke at 0x7f8c7ef6eae8>
         └ <MultiCLI cli>
  File "/data/projects/standalone-fate-master-1.5.0/python/wjc/venv/lib/python3.6/site-packages/click/core.py", line 1259, in invoke
    return _process_result(sub_ctx.command.invoke(sub_ctx))
           │               │       │       │      └ <click.core.Context object at 0x7f8c7f2c1cf8>
           │               │       │       └ <function Command.invoke at 0x7f8c7ef6e730>
           │               │       └ <Command suite>
           │               └ <click.core.Context object at 0x7f8c7f2c1cf8>
           └ <function MultiCommand.invoke.<locals>._process_result at 0x7f8c7f2c0400>
  File "/data/projects/standalone-fate-master-1.5.0/python/wjc/venv/lib/python3.6/site-packages/click/core.py", line 1066, in invoke
    return ctx.invoke(self.callback, **ctx.params)
           │   │      │    │           │   └ {'include': ('../../examples/experiment_template/dsl/v2/hetero_secureboost/hetero_sbt_testsuite.json',), 'exclude': (), 'repl...
           │   │      │    │           └ <click.core.Context object at 0x7f8c7f2c1cf8>
           │   │      │    └ <function run_suite at 0x7f8c4e2478c8>
           │   │      └ <Command suite>
           │   └ <function Context.invoke at 0x7f8c7ef71d90>
           └ <click.core.Context object at 0x7f8c7f2c1cf8>
  File "/data/projects/standalone-fate-master-1.5.0/python/wjc/venv/lib/python3.6/site-packages/click/core.py", line 610, in invoke
    return callback(*args, **kwargs)
           │         │       └ {'include': ('../../examples/experiment_template/dsl/v2/hetero_secureboost/hetero_sbt_testsuite.json',), 'exclude': (), 'repl...
           │         └ ()
           └ <function run_suite at 0x7f8c4e2478c8>
  File "/data/projects/standalone-fate-master-1.5.0/python/wjc/venv/lib/python3.6/site-packages/click/decorators.py", line 21, in new_func
    return f(get_current_context(), *args, **kwargs)
           │ │                       │       └ {'include': ('../../examples/experiment_template/dsl/v2/hetero_secureboost/hetero_sbt_testsuite.json',), 'exclude': (), 'repl...
           │ │                       └ ()
           │ └ <function get_current_context at 0x7f8c7ef78488>
           └ <function run_suite at 0x7f8c4e247840>
  File "/data/projects/standalone-fate-master-1.5.0/python/wjc/venv/lib/python3.6/site-packages/fate_test/scripts/testsuite_cli.py", line 99, in run_suite
    update_component_parameters)
    └ {}
> File "/data/projects/standalone-fate-master-1.5.0/python/wjc/venv/lib/python3.6/site-packages/fate_test/scripts/testsuite_cli.py", line 172, in _submit_job
    response = clients["guest_0"].submit_job(job=job, callback=_call_back)
               │                                 │             └ <function _submit_job.<locals>._call_back at 0x7f8c4e0b2b70>
               │                                 └ <fate_test._parser.Job object at 0x7f8c4e20fd30>
               └ <fate_test._client.Clients object at 0x7f8c86a91630>
  File "/data/projects/standalone-fate-master-1.5.0/python/wjc/venv/lib/python3.6/site-packages/fate_test/_flow_client.py", line 69, in submit_job
    raise RuntimeError(f"submit job failed") from e

RuntimeError: submit job failed
2020-12-14 15:04:11.879 | ERROR    | fate_test.scripts.testsuite_cli:_raise:142 - exception id: 91895274-3dda-11eb-997d-5254009c6d10
Traceback (most recent call last):

  File "/data/projects/standalone-fate-master-1.5.0/python/wjc/venv/lib/python3.6/site-packages/fate_test/_flow_client.py", line 62, in submit_job
    response = self._submit_job(**job.submit_params)
               │    │             │   └ <property object at 0x7f8c7b5c4458>
               │    │             └ <fate_test._parser.Job object at 0x7f8c4e195c88>
               │    └ <function FLOWClient._submit_job at 0x7f8c78db3950>
               └ <fate_test._flow_client.FLOWClient object at 0x7f8c79acd240>
  File "/data/projects/standalone-fate-master-1.5.0/python/wjc/venv/lib/python3.6/site-packages/fate_test/_flow_client.py", line 137, in _submit_job
    response = SubmitJobResponse(self.flow_client(request='job/submit', param=param))
               │                 │    │                                       └ {'job_dsl': '/data/projects/standalone-fate-master-1.5.0/python/fate_test/cache/submit_dsl.json', 'job_runtime_conf': '/data/...
               │                 │    └ <function FLOWClient.flow_client at 0x7f8c78db3bf8>
               │                 └ <fate_test._flow_client.FLOWClient object at 0x7f8c79acd240>
               └ <class 'fate_test._flow_client.SubmitJobResponse'>
  File "/data/projects/standalone-fate-master-1.5.0/python/wjc/venv/lib/python3.6/site-packages/fate_test/_flow_client.py", line 195, in flow_client
    'retmsg': "Internal server error. Nothing in response. You may check out the configuration in "

ValueError: {'retcode': 100, 'retmsg': "Internal server error. Nothing in response. You may check out the configuration in 'FATE/conf/server_conf.yaml' and restart fate flow server."}


The above exception was the direct cause of the following exception:


Traceback (most recent call last):

  File "/data/projects/standalone-fate-master-1.5.0/python/wjc/venv/bin/fate_test", line 8, in <module>
    sys.exit(cli())
    │   │    └ <MultiCLI cli>
    │   └ <built-in function exit>
    └ <module 'sys' (built-in)>
  File "/data/projects/standalone-fate-master-1.5.0/python/wjc/venv/lib/python3.6/site-packages/click/core.py", line 829, in __call__
    return self.main(*args, **kwargs)
           │    │     │       └ {}
           │    │     └ ()
           │    └ <function BaseCommand.main at 0x7f8c7ecf3d90>
           └ <MultiCLI cli>
  File "/data/projects/standalone-fate-master-1.5.0/python/wjc/venv/lib/python3.6/site-packages/click/core.py", line 782, in main
    rv = self.invoke(ctx)
         │    │      └ <click.core.Context object at 0x7f8c7f2d0f98>
         │    └ <function MultiCommand.invoke at 0x7f8c7ef6eae8>
         └ <MultiCLI cli>
  File "/data/projects/standalone-fate-master-1.5.0/python/wjc/venv/lib/python3.6/site-packages/click/core.py", line 1259, in invoke
    return _process_result(sub_ctx.command.invoke(sub_ctx))
           │               │       │       │      └ <click.core.Context object at 0x7f8c7f2c1cf8>
           │               │       │       └ <function Command.invoke at 0x7f8c7ef6e730>
           │               │       └ <Command suite>
           │               └ <click.core.Context object at 0x7f8c7f2c1cf8>
           └ <function MultiCommand.invoke.<locals>._process_result at 0x7f8c7f2c0400>
  File "/data/projects/standalone-fate-master-1.5.0/python/wjc/venv/lib/python3.6/site-packages/click/core.py", line 1066, in invoke
    return ctx.invoke(self.callback, **ctx.params)
           │   │      │    │           │   └ {'include': ('../../examples/experiment_template/dsl/v2/hetero_secureboost/hetero_sbt_testsuite.json',), 'exclude': (), 'repl...
           │   │      │    │           └ <click.core.Context object at 0x7f8c7f2c1cf8>
           │   │      │    └ <function run_suite at 0x7f8c4e2478c8>
           │   │      └ <Command suite>
           │   └ <function Context.invoke at 0x7f8c7ef71d90>
           └ <click.core.Context object at 0x7f8c7f2c1cf8>
  File "/data/projects/standalone-fate-master-1.5.0/python/wjc/venv/lib/python3.6/site-packages/click/core.py", line 610, in invoke
    return callback(*args, **kwargs)
           │         │       └ {'include': ('../../examples/experiment_template/dsl/v2/hetero_secureboost/hetero_sbt_testsuite.json',), 'exclude': (), 'repl...
           │         └ ()
           └ <function run_suite at 0x7f8c4e2478c8>
  File "/data/projects/standalone-fate-master-1.5.0/python/wjc/venv/lib/python3.6/site-packages/click/decorators.py", line 21, in new_func
    return f(get_current_context(), *args, **kwargs)
           │ │                       │       └ {'include': ('../../examples/experiment_template/dsl/v2/hetero_secureboost/hetero_sbt_testsuite.json',), 'exclude': (), 'repl...
           │ │                       └ ()
           │ └ <function get_current_context at 0x7f8c7ef78488>
           └ <function run_suite at 0x7f8c4e247840>
  File "/data/projects/standalone-fate-master-1.5.0/python/wjc/venv/lib/python3.6/site-packages/fate_test/scripts/testsuite_cli.py", line 99, in run_suite
    update_component_parameters)
    └ {}
> File "/data/projects/standalone-fate-master-1.5.0/python/wjc/venv/lib/python3.6/site-packages/fate_test/scripts/testsuite_cli.py", line 172, in _submit_job
    response = clients["guest_0"].submit_job(job=job, callback=_call_back)
               │                                 │             └ <function _submit_job.<locals>._call_back at 0x7f8c4e137e18>
               │                                 └ <fate_test._parser.Job object at 0x7f8c4e195c88>
               └ <fate_test._client.Clients object at 0x7f8c86a91630>
  File "/data/projects/standalone-fate-master-1.5.0/python/wjc/venv/lib/python3.6/site-packages/fate_test/_flow_client.py", line 69, in submit_job
    raise RuntimeError(f"submit job failed") from e

RuntimeError: submit job failed
2020-12-14 15:04:12.085 | ERROR    | fate_test.scripts.testsuite_cli:_raise:142 - exception id: 91a8d554-3dda-11eb-997d-5254009c6d10
Traceback (most recent call last):

  File "/data/projects/standalone-fate-master-1.5.0/python/wjc/venv/lib/python3.6/site-packages/fate_test/_flow_client.py", line 62, in submit_job
    response = self._submit_job(**job.submit_params)
               │    │             │   └ <property object at 0x7f8c7b5c4458>
               │    │             └ <fate_test._parser.Job object at 0x7f8c4e1a0be0>
               │    └ <function FLOWClient._submit_job at 0x7f8c78db3950>
               └ <fate_test._flow_client.FLOWClient object at 0x7f8c79acd240>
  File "/data/projects/standalone-fate-master-1.5.0/python/wjc/venv/lib/python3.6/site-packages/fate_test/_flow_client.py", line 137, in _submit_job
    response = SubmitJobResponse(self.flow_client(request='job/submit', param=param))
               │                 │    │                                       └ {'job_dsl': '/data/projects/standalone-fate-master-1.5.0/python/fate_test/cache/submit_dsl.json', 'job_runtime_conf': '/data/...
               │                 │    └ <function FLOWClient.flow_client at 0x7f8c78db3bf8>
               │                 └ <fate_test._flow_client.FLOWClient object at 0x7f8c79acd240>
               └ <class 'fate_test._flow_client.SubmitJobResponse'>
  File "/data/projects/standalone-fate-master-1.5.0/python/wjc/venv/lib/python3.6/site-packages/fate_test/_flow_client.py", line 195, in flow_client
    'retmsg': "Internal server error. Nothing in response. You may check out the configuration in "

ValueError: {'retcode': 100, 'retmsg': "Internal server error. Nothing in response. You may check out the configuration in 'FATE/conf/server_conf.yaml' and restart fate flow server."}


The above exception was the direct cause of the following exception:


Traceback (most recent call last):

  File "/data/projects/standalone-fate-master-1.5.0/python/wjc/venv/bin/fate_test", line 8, in <module>
    sys.exit(cli())
    │   │    └ <MultiCLI cli>
    │   └ <built-in function exit>
    └ <module 'sys' (built-in)>
  File "/data/projects/standalone-fate-master-1.5.0/python/wjc/venv/lib/python3.6/site-packages/click/core.py", line 829, in __call__
    return self.main(*args, **kwargs)
           │    │     │       └ {}
           │    │     └ ()
           │    └ <function BaseCommand.main at 0x7f8c7ecf3d90>
           └ <MultiCLI cli>
  File "/data/projects/standalone-fate-master-1.5.0/python/wjc/venv/lib/python3.6/site-packages/click/core.py", line 782, in main
    rv = self.invoke(ctx)
         │    │      └ <click.core.Context object at 0x7f8c7f2d0f98>
         │    └ <function MultiCommand.invoke at 0x7f8c7ef6eae8>
         └ <MultiCLI cli>
  File "/data/projects/standalone-fate-master-1.5.0/python/wjc/venv/lib/python3.6/site-packages/click/core.py", line 1259, in invoke
    return _process_result(sub_ctx.command.invoke(sub_ctx))
           │               │       │       │      └ <click.core.Context object at 0x7f8c7f2c1cf8>
           │               │       │       └ <function Command.invoke at 0x7f8c7ef6e730>
           │               │       └ <Command suite>
           │               └ <click.core.Context object at 0x7f8c7f2c1cf8>
           └ <function MultiCommand.invoke.<locals>._process_result at 0x7f8c7f2c0400>
  File "/data/projects/standalone-fate-master-1.5.0/python/wjc/venv/lib/python3.6/site-packages/click/core.py", line 1066, in invoke
    return ctx.invoke(self.callback, **ctx.params)
           │   │      │    │           │   └ {'include': ('../../examples/experiment_template/dsl/v2/hetero_secureboost/hetero_sbt_testsuite.json',), 'exclude': (), 'repl...
           │   │      │    │           └ <click.core.Context object at 0x7f8c7f2c1cf8>
           │   │      │    └ <function run_suite at 0x7f8c4e2478c8>
           │   │      └ <Command suite>
           │   └ <function Context.invoke at 0x7f8c7ef71d90>
           └ <click.core.Context object at 0x7f8c7f2c1cf8>
  File "/data/projects/standalone-fate-master-1.5.0/python/wjc/venv/lib/python3.6/site-packages/click/core.py", line 610, in invoke
    return callback(*args, **kwargs)
           │         │       └ {'include': ('../../examples/experiment_template/dsl/v2/hetero_secureboost/hetero_sbt_testsuite.json',), 'exclude': (), 'repl...
           │         └ ()
           └ <function run_suite at 0x7f8c4e2478c8>
  File "/data/projects/standalone-fate-master-1.5.0/python/wjc/venv/lib/python3.6/site-packages/click/decorators.py", line 21, in new_func
    return f(get_current_context(), *args, **kwargs)
           │ │                       │       └ {'include': ('../../examples/experiment_template/dsl/v2/hetero_secureboost/hetero_sbt_testsuite.json',), 'exclude': (), 'repl...
           │ │                       └ ()
           │ └ <function get_current_context at 0x7f8c7ef78488>
           └ <function run_suite at 0x7f8c4e247840>
  File "/data/projects/standalone-fate-master-1.5.0/python/wjc/venv/lib/python3.6/site-packages/fate_test/scripts/testsuite_cli.py", line 99, in run_suite
    update_component_parameters)
    └ {}
> File "/data/projects/standalone-fate-master-1.5.0/python/wjc/venv/lib/python3.6/site-packages/fate_test/scripts/testsuite_cli.py", line 172, in _submit_job
    response = clients["guest_0"].submit_job(job=job, callback=_call_back)
               │                                 │             └ <function _submit_job.<locals>._call_back at 0x7f8c4e0c4730>
               │                                 └ <fate_test._parser.Job object at 0x7f8c4e1a0be0>
               └ <fate_test._client.Clients object at 0x7f8c86a91630>
  File "/data/projects/standalone-fate-master-1.5.0/python/wjc/venv/lib/python3.6/site-packages/fate_test/_flow_client.py", line 69, in submit_job
    raise RuntimeError(f"submit job failed") from e

RuntimeError: submit job failed
2020-12-14 15:04:12.292 | ERROR    | fate_test.scripts.testsuite_cli:_raise:142 - exception id: 91c86ae0-3dda-11eb-997d-5254009c6d10
Traceback (most recent call last):

  File "/data/projects/standalone-fate-master-1.5.0/python/wjc/venv/lib/python3.6/site-packages/fate_test/_flow_client.py", line 62, in submit_job
    response = self._submit_job(**job.submit_params)
               │    │             │   └ <property object at 0x7f8c7b5c4458>
               │    │             └ <fate_test._parser.Job object at 0x7f8c4e1a6b70>
               │    └ <function FLOWClient._submit_job at 0x7f8c78db3950>
               └ <fate_test._flow_client.FLOWClient object at 0x7f8c79acd240>
  File "/data/projects/standalone-fate-master-1.5.0/python/wjc/venv/lib/python3.6/site-packages/fate_test/_flow_client.py", line 137, in _submit_job
    response = SubmitJobResponse(self.flow_client(request='job/submit', param=param))
               │                 │    │                                       └ {'job_dsl': '/data/projects/standalone-fate-master-1.5.0/python/fate_test/cache/submit_dsl.json', 'job_runtime_conf': '/data/...
               │                 │    └ <function FLOWClient.flow_client at 0x7f8c78db3bf8>
               │                 └ <fate_test._flow_client.FLOWClient object at 0x7f8c79acd240>
               └ <class 'fate_test._flow_client.SubmitJobResponse'>
  File "/data/projects/standalone-fate-master-1.5.0/python/wjc/venv/lib/python3.6/site-packages/fate_test/_flow_client.py", line 195, in flow_client
    'retmsg': "Internal server error. Nothing in response. You may check out the configuration in "

ValueError: {'retcode': 100, 'retmsg': "Internal server error. Nothing in response. You may check out the configuration in 'FATE/conf/server_conf.yaml' and restart fate flow server."}


The above exception was the direct cause of the following exception:


Traceback (most recent call last):

  File "/data/projects/standalone-fate-master-1.5.0/python/wjc/venv/bin/fate_test", line 8, in <module>
    sys.exit(cli())
    │   │    └ <MultiCLI cli>
    │   └ <built-in function exit>
    └ <module 'sys' (built-in)>
  File "/data/projects/standalone-fate-master-1.5.0/python/wjc/venv/lib/python3.6/site-packages/click/core.py", line 829, in __call__
    return self.main(*args, **kwargs)
           │    │     │       └ {}
           │    │     └ ()
           │    └ <function BaseCommand.main at 0x7f8c7ecf3d90>
           └ <MultiCLI cli>
  File "/data/projects/standalone-fate-master-1.5.0/python/wjc/venv/lib/python3.6/site-packages/click/core.py", line 782, in main
    rv = self.invoke(ctx)
         │    │      └ <click.core.Context object at 0x7f8c7f2d0f98>
         │    └ <function MultiCommand.invoke at 0x7f8c7ef6eae8>
         └ <MultiCLI cli>
  File "/data/projects/standalone-fate-master-1.5.0/python/wjc/venv/lib/python3.6/site-packages/click/core.py", line 1259, in invoke
    return _process_result(sub_ctx.command.invoke(sub_ctx))
           │               │       │       │      └ <click.core.Context object at 0x7f8c7f2c1cf8>
           │               │       │       └ <function Command.invoke at 0x7f8c7ef6e730>
           │               │       └ <Command suite>
           │               └ <click.core.Context object at 0x7f8c7f2c1cf8>
           └ <function MultiCommand.invoke.<locals>._process_result at 0x7f8c7f2c0400>
  File "/data/projects/standalone-fate-master-1.5.0/python/wjc/venv/lib/python3.6/site-packages/click/core.py", line 1066, in invoke
    return ctx.invoke(self.callback, **ctx.params)
           │   │      │    │           │   └ {'include': ('../../examples/experiment_template/dsl/v2/hetero_secureboost/hetero_sbt_testsuite.json',), 'exclude': (), 'repl...
           │   │      │    │           └ <click.core.Context object at 0x7f8c7f2c1cf8>
           │   │      │    └ <function run_suite at 0x7f8c4e2478c8>
           │   │      └ <Command suite>
           │   └ <function Context.invoke at 0x7f8c7ef71d90>
           └ <click.core.Context object at 0x7f8c7f2c1cf8>
  File "/data/projects/standalone-fate-master-1.5.0/python/wjc/venv/lib/python3.6/site-packages/click/core.py", line 610, in invoke
    return callback(*args, **kwargs)
           │         │       └ {'include': ('../../examples/experiment_template/dsl/v2/hetero_secureboost/hetero_sbt_testsuite.json',), 'exclude': (), 'repl...
           │         └ ()
           └ <function run_suite at 0x7f8c4e2478c8>
  File "/data/projects/standalone-fate-master-1.5.0/python/wjc/venv/lib/python3.6/site-packages/click/decorators.py", line 21, in new_func
    return f(get_current_context(), *args, **kwargs)
           │ │                       │       └ {'include': ('../../examples/experiment_template/dsl/v2/hetero_secureboost/hetero_sbt_testsuite.json',), 'exclude': (), 'repl...
           │ │                       └ ()
           │ └ <function get_current_context at 0x7f8c7ef78488>
           └ <function run_suite at 0x7f8c4e247840>
  File "/data/projects/standalone-fate-master-1.5.0/python/wjc/venv/lib/python3.6/site-packages/fate_test/scripts/testsuite_cli.py", line 99, in run_suite
    update_component_parameters)
    └ {}
> File "/data/projects/standalone-fate-master-1.5.0/python/wjc/venv/lib/python3.6/site-packages/fate_test/scripts/testsuite_cli.py", line 172, in _submit_job
    response = clients["guest_0"].submit_job(job=job, callback=_call_back)
               │                                 │             └ <function _submit_job.<locals>._call_back at 0x7f8c4e0c4ae8>
               │                                 └ <fate_test._parser.Job object at 0x7f8c4e1a6b70>
               └ <fate_test._client.Clients object at 0x7f8c86a91630>
  File "/data/projects/standalone-fate-master-1.5.0/python/wjc/venv/lib/python3.6/site-packages/fate_test/_flow_client.py", line 69, in submit_job
    raise RuntimeError(f"submit job failed") from e

RuntimeError: submit job failed
2020-12-14 15:04:12.499 | ERROR    | fate_test.scripts.testsuite_cli:_raise:142 - exception id: 91e7e104-3dda-11eb-997d-5254009c6d10
Traceback (most recent call last):

  File "/data/projects/standalone-fate-master-1.5.0/python/wjc/venv/lib/python3.6/site-packages/fate_test/_flow_client.py", line 62, in submit_job
    response = self._submit_job(**job.submit_params)
               │    │             │   └ <property object at 0x7f8c7b5c4458>
               │    │             └ <fate_test._parser.Job object at 0x7f8c4e1b3e10>
               │    └ <function FLOWClient._submit_job at 0x7f8c78db3950>
               └ <fate_test._flow_client.FLOWClient object at 0x7f8c79acd240>
  File "/data/projects/standalone-fate-master-1.5.0/python/wjc/venv/lib/python3.6/site-packages/fate_test/_flow_client.py", line 137, in _submit_job
    response = SubmitJobResponse(self.flow_client(request='job/submit', param=param))
               │                 │    │                                       └ {'job_dsl': '/data/projects/standalone-fate-master-1.5.0/python/fate_test/cache/submit_dsl.json', 'job_runtime_conf': '/data/...
               │                 │    └ <function FLOWClient.flow_client at 0x7f8c78db3bf8>
               │                 └ <fate_test._flow_client.FLOWClient object at 0x7f8c79acd240>
               └ <class 'fate_test._flow_client.SubmitJobResponse'>
  File "/data/projects/standalone-fate-master-1.5.0/python/wjc/venv/lib/python3.6/site-packages/fate_test/_flow_client.py", line 195, in flow_client
    'retmsg': "Internal server error. Nothing in response. You may check out the configuration in "

ValueError: {'retcode': 100, 'retmsg': "Internal server error. Nothing in response. You may check out the configuration in 'FATE/conf/server_conf.yaml' and restart fate flow server."}


The above exception was the direct cause of the following exception:


Traceback (most recent call last):

  File "/data/projects/standalone-fate-master-1.5.0/python/wjc/venv/bin/fate_test", line 8, in <module>
    sys.exit(cli())
    │   │    └ <MultiCLI cli>
    │   └ <built-in function exit>
    └ <module 'sys' (built-in)>
  File "/data/projects/standalone-fate-master-1.5.0/python/wjc/venv/lib/python3.6/site-packages/click/core.py", line 829, in __call__
    return self.main(*args, **kwargs)
           │    │     │       └ {}
           │    │     └ ()
           │    └ <function BaseCommand.main at 0x7f8c7ecf3d90>
           └ <MultiCLI cli>
  File "/data/projects/standalone-fate-master-1.5.0/python/wjc/venv/lib/python3.6/site-packages/click/core.py", line 782, in main
    rv = self.invoke(ctx)
         │    │      └ <click.core.Context object at 0x7f8c7f2d0f98>
         │    └ <function MultiCommand.invoke at 0x7f8c7ef6eae8>
         └ <MultiCLI cli>
  File "/data/projects/standalone-fate-master-1.5.0/python/wjc/venv/lib/python3.6/site-packages/click/core.py", line 1259, in invoke
    return _process_result(sub_ctx.command.invoke(sub_ctx))
           │               │       │       │      └ <click.core.Context object at 0x7f8c7f2c1cf8>
           │               │       │       └ <function Command.invoke at 0x7f8c7ef6e730>
           │               │       └ <Command suite>
           │               └ <click.core.Context object at 0x7f8c7f2c1cf8>
           └ <function MultiCommand.invoke.<locals>._process_result at 0x7f8c7f2c0400>
  File "/data/projects/standalone-fate-master-1.5.0/python/wjc/venv/lib/python3.6/site-packages/click/core.py", line 1066, in invoke
    return ctx.invoke(self.callback, **ctx.params)
           │   │      │    │           │   └ {'include': ('../../examples/experiment_template/dsl/v2/hetero_secureboost/hetero_sbt_testsuite.json',), 'exclude': (), 'repl...
           │   │      │    │           └ <click.core.Context object at 0x7f8c7f2c1cf8>
           │   │      │    └ <function run_suite at 0x7f8c4e2478c8>
           │   │      └ <Command suite>
           │   └ <function Context.invoke at 0x7f8c7ef71d90>
           └ <click.core.Context object at 0x7f8c7f2c1cf8>
  File "/data/projects/standalone-fate-master-1.5.0/python/wjc/venv/lib/python3.6/site-packages/click/core.py", line 610, in invoke
    return callback(*args, **kwargs)
           │         │       └ {'include': ('../../examples/experiment_template/dsl/v2/hetero_secureboost/hetero_sbt_testsuite.json',), 'exclude': (), 'repl...
           │         └ ()
           └ <function run_suite at 0x7f8c4e2478c8>
  File "/data/projects/standalone-fate-master-1.5.0/python/wjc/venv/lib/python3.6/site-packages/click/decorators.py", line 21, in new_func
    return f(get_current_context(), *args, **kwargs)
           │ │                       │       └ {'include': ('../../examples/experiment_template/dsl/v2/hetero_secureboost/hetero_sbt_testsuite.json',), 'exclude': (), 'repl...
           │ │                       └ ()
           │ └ <function get_current_context at 0x7f8c7ef78488>
           └ <function run_suite at 0x7f8c4e247840>
  File "/data/projects/standalone-fate-master-1.5.0/python/wjc/venv/lib/python3.6/site-packages/fate_test/scripts/testsuite_cli.py", line 99, in run_suite
    update_component_parameters)
    └ {}
> File "/data/projects/standalone-fate-master-1.5.0/python/wjc/venv/lib/python3.6/site-packages/fate_test/scripts/testsuite_cli.py", line 172, in _submit_job
    response = clients["guest_0"].submit_job(job=job, callback=_call_back)
               │                                 │             └ <function _submit_job.<locals>._call_back at 0x7f8c4e0c4bf8>
               │                                 └ <fate_test._parser.Job object at 0x7f8c4e1b3e10>
               └ <fate_test._client.Clients object at 0x7f8c86a91630>
  File "/data/projects/standalone-fate-master-1.5.0/python/wjc/venv/lib/python3.6/site-packages/fate_test/_flow_client.py", line 69, in submit_job
    raise RuntimeError(f"submit job failed") from e

RuntimeError: submit job failed
2020-12-14 15:04:12.603 | ERROR    | fate_test.scripts._utils:_delete_data:142 - delete failed: name=breast_hetero_guest, namespace=experiment
Traceback (most recent call last):

  File "/data/projects/standalone-fate-master-1.5.0/python/wjc/venv/lib/python3.6/site-packages/fate_test/_flow_client.py", line 56, in delete_data
    self._delete_data(table_name=data.config['table_name'], namespace=data.config['namespace'])
    │    │                       │    │                               │    └ {'head': 1, 'partition': 4, 'table_name': 'breast_hetero_guest', 'namespace': 'experiment', 'file': '/data/projects/standalon...
    │    │                       │    │                               └ <fate_test._parser.Data object at 0x7f8c4e1d95f8>
    │    │                       │    └ {'head': 1, 'partition': 4, 'table_name': 'breast_hetero_guest', 'namespace': 'experiment', 'file': '/data/projects/standalon...
    │    │                       └ <fate_test._parser.Data object at 0x7f8c4e1d95f8>
    │    └ <function FLOWClient._delete_data at 0x7f8c78db38c8>
    └ <fate_test._flow_client.FLOWClient object at 0x7f8c79acd240>
  File "/data/projects/standalone-fate-master-1.5.0/python/wjc/venv/lib/python3.6/site-packages/fate_test/_flow_client.py", line 129, in _delete_data
    response = self.flow_client(request='table/delete', param=param)
               │    │                                         └ {'table_name': 'breast_hetero_guest', 'namespace': 'experiment'}
               │    └ <function FLOWClient.flow_client at 0x7f8c78db3bf8>
               └ <fate_test._flow_client.FLOWClient object at 0x7f8c79acd240>
  File "/data/projects/standalone-fate-master-1.5.0/python/wjc/venv/lib/python3.6/site-packages/fate_test/_flow_client.py", line 195, in flow_client
    'retmsg': "Internal server error. Nothing in response. You may check out the configuration in "

ValueError: {'retcode': 100, 'retmsg': "Internal server error. Nothing in response. You may check out the configuration in 'FATE/conf/server_conf.yaml' and restart fate flow server."}


The above exception was the direct cause of the following exception:


Traceback (most recent call last):

  File "/data/projects/standalone-fate-master-1.5.0/python/wjc/venv/bin/fate_test", line 8, in <module>
    sys.exit(cli())
    │   │    └ <MultiCLI cli>
    │   └ <built-in function exit>
    └ <module 'sys' (built-in)>
  File "/data/projects/standalone-fate-master-1.5.0/python/wjc/venv/lib/python3.6/site-packages/click/core.py", line 829, in __call__
    return self.main(*args, **kwargs)
           │    │     │       └ {}
           │    │     └ ()
           │    └ <function BaseCommand.main at 0x7f8c7ecf3d90>
           └ <MultiCLI cli>
  File "/data/projects/standalone-fate-master-1.5.0/python/wjc/venv/lib/python3.6/site-packages/click/core.py", line 782, in main
    rv = self.invoke(ctx)
         │    │      └ <click.core.Context object at 0x7f8c7f2d0f98>
         │    └ <function MultiCommand.invoke at 0x7f8c7ef6eae8>
         └ <MultiCLI cli>
  File "/data/projects/standalone-fate-master-1.5.0/python/wjc/venv/lib/python3.6/site-packages/click/core.py", line 1259, in invoke
    return _process_result(sub_ctx.command.invoke(sub_ctx))
           │               │       │       │      └ <click.core.Context object at 0x7f8c7f2c1cf8>
           │               │       │       └ <function Command.invoke at 0x7f8c7ef6e730>
           │               │       └ <Command suite>
           │               └ <click.core.Context object at 0x7f8c7f2c1cf8>
           └ <function MultiCommand.invoke.<locals>._process_result at 0x7f8c7f2c0400>
  File "/data/projects/standalone-fate-master-1.5.0/python/wjc/venv/lib/python3.6/site-packages/click/core.py", line 1066, in invoke
    return ctx.invoke(self.callback, **ctx.params)
           │   │      │    │           │   └ {'include': ('../../examples/experiment_template/dsl/v2/hetero_secureboost/hetero_sbt_testsuite.json',), 'exclude': (), 'repl...
           │   │      │    │           └ <click.core.Context object at 0x7f8c7f2c1cf8>
           │   │      │    └ <function run_suite at 0x7f8c4e2478c8>
           │   │      └ <Command suite>
           │   └ <function Context.invoke at 0x7f8c7ef71d90>
           └ <click.core.Context object at 0x7f8c7f2c1cf8>
  File "/data/projects/standalone-fate-master-1.5.0/python/wjc/venv/lib/python3.6/site-packages/click/core.py", line 610, in invoke
    return callback(*args, **kwargs)
           │         │       └ {'include': ('../../examples/experiment_template/dsl/v2/hetero_secureboost/hetero_sbt_testsuite.json',), 'exclude': (), 'repl...
           │         └ ()
           └ <function run_suite at 0x7f8c4e2478c8>
  File "/data/projects/standalone-fate-master-1.5.0/python/wjc/venv/lib/python3.6/site-packages/click/decorators.py", line 21, in new_func
    return f(get_current_context(), *args, **kwargs)
           │ │                       │       └ {'include': ('../../examples/experiment_template/dsl/v2/hetero_secureboost/hetero_sbt_testsuite.json',), 'exclude': (), 'repl...
           │ │                       └ ()
           │ └ <function get_current_context at 0x7f8c7ef78488>
           └ <function run_suite at 0x7f8c4e247840>
  File "/data/projects/standalone-fate-master-1.5.0/python/wjc/venv/lib/python3.6/site-packages/fate_test/scripts/testsuite_cli.py", line 110, in run_suite
    _delete_data(client, suite)
    │            │       └ <fate_test._parser.Testsuite object at 0x7f8c4e1b3dd8>
    │            └ <fate_test._client.Clients object at 0x7f8c86a91630>
    └ <function _delete_data at 0x7f8c4e233b70>
> File "/data/projects/standalone-fate-master-1.5.0/python/wjc/venv/lib/python3.6/site-packages/fate_test/scripts/_utils.py", line 139, in _delete_data
    clients[data.role_str].delete_data(data)
    │       │    │                     └ <fate_test._parser.Data object at 0x7f8c4e1d95f8>
    │       │    └ 'guest_0'
    │       └ <fate_test._parser.Data object at 0x7f8c4e1d95f8>
    └ <fate_test._client.Clients object at 0x7f8c86a91630>
  File "/data/projects/standalone-fate-master-1.5.0/python/wjc/venv/lib/python3.6/site-packages/fate_test/_flow_client.py", line 58, in delete_data
    raise RuntimeError(f"delete data failed") from e

RuntimeError: delete data failed
2020-12-14 15:04:13.108 | ERROR    | fate_test.scripts._utils:_delete_data:142 - delete failed: name=breast_hetero_host_tag_value, namespace=experiment
Traceback (most recent call last):

  File "/data/projects/standalone-fate-master-1.5.0/python/wjc/venv/lib/python3.6/site-packages/fate_test/_flow_client.py", line 56, in delete_data
    self._delete_data(table_name=data.config['table_name'], namespace=data.config['namespace'])
    │    │                       │    │                               │    └ {'head': 1, 'partition': 4, 'table_name': 'breast_hetero_host_tag_value', 'namespace': 'experiment', 'file': '/data/projects/...
    │    │                       │    │                               └ <fate_test._parser.Data object at 0x7f8c4e1d9588>
    │    │                       │    └ {'head': 1, 'partition': 4, 'table_name': 'breast_hetero_host_tag_value', 'namespace': 'experiment', 'file': '/data/projects/...
    │    │                       └ <fate_test._parser.Data object at 0x7f8c4e1d9588>
    │    └ <function FLOWClient._delete_data at 0x7f8c78db38c8>
    └ <fate_test._flow_client.FLOWClient object at 0x7f8c79acd240>
  File "/data/projects/standalone-fate-master-1.5.0/python/wjc/venv/lib/python3.6/site-packages/fate_test/_flow_client.py", line 129, in _delete_data
    response = self.flow_client(request='table/delete', param=param)
               │    │                                         └ {'table_name': 'breast_hetero_host_tag_value', 'namespace': 'experiment'}
               │    └ <function FLOWClient.flow_client at 0x7f8c78db3bf8>
               └ <fate_test._flow_client.FLOWClient object at 0x7f8c79acd240>
  File "/data/projects/standalone-fate-master-1.5.0/python/wjc/venv/lib/python3.6/site-packages/fate_test/_flow_client.py", line 195, in flow_client
    'retmsg': "Internal server error. Nothing in response. You may check out the configuration in "

ValueError: {'retcode': 100, 'retmsg': "Internal server error. Nothing in response. You may check out the configuration in 'FATE/conf/server_conf.yaml' and restart fate flow server."}


The above exception was the direct cause of the following exception:


Traceback (most recent call last):

  File "/data/projects/standalone-fate-master-1.5.0/python/wjc/venv/bin/fate_test", line 8, in <module>
    sys.exit(cli())
    │   │    └ <MultiCLI cli>
    │   └ <built-in function exit>
    └ <module 'sys' (built-in)>
  File "/data/projects/standalone-fate-master-1.5.0/python/wjc/venv/lib/python3.6/site-packages/click/core.py", line 829, in __call__
    return self.main(*args, **kwargs)
           │    │     │       └ {}
           │    │     └ ()
           │    └ <function BaseCommand.main at 0x7f8c7ecf3d90>
           └ <MultiCLI cli>
  File "/data/projects/standalone-fate-master-1.5.0/python/wjc/venv/lib/python3.6/site-packages/click/core.py", line 782, in main
    rv = self.invoke(ctx)
         │    │      └ <click.core.Context object at 0x7f8c7f2d0f98>
         │    └ <function MultiCommand.invoke at 0x7f8c7ef6eae8>
         └ <MultiCLI cli>
  File "/data/projects/standalone-fate-master-1.5.0/python/wjc/venv/lib/python3.6/site-packages/click/core.py", line 1259, in invoke
    return _process_result(sub_ctx.command.invoke(sub_ctx))
           │               │       │       │      └ <click.core.Context object at 0x7f8c7f2c1cf8>
           │               │       │       └ <function Command.invoke at 0x7f8c7ef6e730>
           │               │       └ <Command suite>
           │               └ <click.core.Context object at 0x7f8c7f2c1cf8>
           └ <function MultiCommand.invoke.<locals>._process_result at 0x7f8c7f2c0400>
  File "/data/projects/standalone-fate-master-1.5.0/python/wjc/venv/lib/python3.6/site-packages/click/core.py", line 1066, in invoke
    return ctx.invoke(self.callback, **ctx.params)
           │   │      │    │           │   └ {'include': ('../../examples/experiment_template/dsl/v2/hetero_secureboost/hetero_sbt_testsuite.json',), 'exclude': (), 'repl...
           │   │      │    │           └ <click.core.Context object at 0x7f8c7f2c1cf8>
           │   │      │    └ <function run_suite at 0x7f8c4e2478c8>
           │   │      └ <Command suite>
           │   └ <function Context.invoke at 0x7f8c7ef71d90>
           └ <click.core.Context object at 0x7f8c7f2c1cf8>
  File "/data/projects/standalone-fate-master-1.5.0/python/wjc/venv/lib/python3.6/site-packages/click/core.py", line 610, in invoke
    return callback(*args, **kwargs)
           │         │       └ {'include': ('../../examples/experiment_template/dsl/v2/hetero_secureboost/hetero_sbt_testsuite.json',), 'exclude': (), 'repl...
           │         └ ()
           └ <function run_suite at 0x7f8c4e2478c8>
  File "/data/projects/standalone-fate-master-1.5.0/python/wjc/venv/lib/python3.6/site-packages/click/decorators.py", line 21, in new_func
    return f(get_current_context(), *args, **kwargs)
           │ │                       │       └ {'include': ('../../examples/experiment_template/dsl/v2/hetero_secureboost/hetero_sbt_testsuite.json',), 'exclude': (), 'repl...
           │ │                       └ ()
           │ └ <function get_current_context at 0x7f8c7ef78488>
           └ <function run_suite at 0x7f8c4e247840>
  File "/data/projects/standalone-fate-master-1.5.0/python/wjc/venv/lib/python3.6/site-packages/fate_test/scripts/testsuite_cli.py", line 110, in run_suite
    _delete_data(client, suite)
    │            │       └ <fate_test._parser.Testsuite object at 0x7f8c4e1b3dd8>
    │            └ <fate_test._client.Clients object at 0x7f8c86a91630>
    └ <function _delete_data at 0x7f8c4e233b70>
> File "/data/projects/standalone-fate-master-1.5.0/python/wjc/venv/lib/python3.6/site-packages/fate_test/scripts/_utils.py", line 139, in _delete_data
    clients[data.role_str].delete_data(data)
    │       │    │                     └ <fate_test._parser.Data object at 0x7f8c4e1d9588>
    │       │    └ 'host_0'
    │       └ <fate_test._parser.Data object at 0x7f8c4e1d9588>
    └ <fate_test._client.Clients object at 0x7f8c86a91630>
  File "/data/projects/standalone-fate-master-1.5.0/python/wjc/venv/lib/python3.6/site-packages/fate_test/_flow_client.py", line 58, in delete_data
    raise RuntimeError(f"delete data failed") from e

RuntimeError: delete data failed
2020-12-14 15:04:13.613 | ERROR    | fate_test.scripts._utils:_delete_data:142 - delete failed: name=mock_tag_hetero_host, namespace=experiment
Traceback (most recent call last):

  File "/data/projects/standalone-fate-master-1.5.0/python/wjc/venv/lib/python3.6/site-packages/fate_test/_flow_client.py", line 56, in delete_data
    self._delete_data(table_name=data.config['table_name'], namespace=data.config['namespace'])
    │    │                       │    │                               │    └ {'head': 1, 'partition': 4, 'table_name': 'mock_tag_hetero_host', 'namespace': 'experiment', 'file': '/data/projects/standalo...
    │    │                       │    │                               └ <fate_test._parser.Data object at 0x7f8c4e1d9710>
    │    │                       │    └ {'head': 1, 'partition': 4, 'table_name': 'mock_tag_hetero_host', 'namespace': 'experiment', 'file': '/data/projects/standalo...
    │    │                       └ <fate_test._parser.Data object at 0x7f8c4e1d9710>
    │    └ <function FLOWClient._delete_data at 0x7f8c78db38c8>
    └ <fate_test._flow_client.FLOWClient object at 0x7f8c79acd240>
  File "/data/projects/standalone-fate-master-1.5.0/python/wjc/venv/lib/python3.6/site-packages/fate_test/_flow_client.py", line 129, in _delete_data
    response = self.flow_client(request='table/delete', param=param)
               │    │                                         └ {'table_name': 'mock_tag_hetero_host', 'namespace': 'experiment'}
               │    └ <function FLOWClient.flow_client at 0x7f8c78db3bf8>
               └ <fate_test._flow_client.FLOWClient object at 0x7f8c79acd240>
  File "/data/projects/standalone-fate-master-1.5.0/python/wjc/venv/lib/python3.6/site-packages/fate_test/_flow_client.py", line 195, in flow_client
    'retmsg': "Internal server error. Nothing in response. You may check out the configuration in "

ValueError: {'retcode': 100, 'retmsg': "Internal server error. Nothing in response. You may check out the configuration in 'FATE/conf/server_conf.yaml' and restart fate flow server."}


The above exception was the direct cause of the following exception:


Traceback (most recent call last):

  File "/data/projects/standalone-fate-master-1.5.0/python/wjc/venv/bin/fate_test", line 8, in <module>
    sys.exit(cli())
    │   │    └ <MultiCLI cli>
    │   └ <built-in function exit>
    └ <module 'sys' (built-in)>
  File "/data/projects/standalone-fate-master-1.5.0/python/wjc/venv/lib/python3.6/site-packages/click/core.py", line 829, in __call__
    return self.main(*args, **kwargs)
           │    │     │       └ {}
           │    │     └ ()
           │    └ <function BaseCommand.main at 0x7f8c7ecf3d90>
           └ <MultiCLI cli>
  File "/data/projects/standalone-fate-master-1.5.0/python/wjc/venv/lib/python3.6/site-packages/click/core.py", line 782, in main
    rv = self.invoke(ctx)
         │    │      └ <click.core.Context object at 0x7f8c7f2d0f98>
         │    └ <function MultiCommand.invoke at 0x7f8c7ef6eae8>
         └ <MultiCLI cli>
  File "/data/projects/standalone-fate-master-1.5.0/python/wjc/venv/lib/python3.6/site-packages/click/core.py", line 1259, in invoke
    return _process_result(sub_ctx.command.invoke(sub_ctx))
           │               │       │       │      └ <click.core.Context object at 0x7f8c7f2c1cf8>
           │               │       │       └ <function Command.invoke at 0x7f8c7ef6e730>
           │               │       └ <Command suite>
           │               └ <click.core.Context object at 0x7f8c7f2c1cf8>
           └ <function MultiCommand.invoke.<locals>._process_result at 0x7f8c7f2c0400>
  File "/data/projects/standalone-fate-master-1.5.0/python/wjc/venv/lib/python3.6/site-packages/click/core.py", line 1066, in invoke
    return ctx.invoke(self.callback, **ctx.params)
           │   │      │    │           │   └ {'include': ('../../examples/experiment_template/dsl/v2/hetero_secureboost/hetero_sbt_testsuite.json',), 'exclude': (), 'repl...
           │   │      │    │           └ <click.core.Context object at 0x7f8c7f2c1cf8>
           │   │      │    └ <function run_suite at 0x7f8c4e2478c8>
           │   │      └ <Command suite>
           │   └ <function Context.invoke at 0x7f8c7ef71d90>
           └ <click.core.Context object at 0x7f8c7f2c1cf8>
  File "/data/projects/standalone-fate-master-1.5.0/python/wjc/venv/lib/python3.6/site-packages/click/core.py", line 610, in invoke
    return callback(*args, **kwargs)
           │         │       └ {'include': ('../../examples/experiment_template/dsl/v2/hetero_secureboost/hetero_sbt_testsuite.json',), 'exclude': (), 'repl...
           │         └ ()
           └ <function run_suite at 0x7f8c4e2478c8>
  File "/data/projects/standalone-fate-master-1.5.0/python/wjc/venv/lib/python3.6/site-packages/click/decorators.py", line 21, in new_func
    return f(get_current_context(), *args, **kwargs)
           │ │                       │       └ {'include': ('../../examples/experiment_template/dsl/v2/hetero_secureboost/hetero_sbt_testsuite.json',), 'exclude': (), 'repl...
           │ │                       └ ()
           │ └ <function get_current_context at 0x7f8c7ef78488>
           └ <function run_suite at 0x7f8c4e247840>
  File "/data/projects/standalone-fate-master-1.5.0/python/wjc/venv/lib/python3.6/site-packages/fate_test/scripts/testsuite_cli.py", line 110, in run_suite
    _delete_data(client, suite)
    │            │       └ <fate_test._parser.Testsuite object at 0x7f8c4e1b3dd8>
    │            └ <fate_test._client.Clients object at 0x7f8c86a91630>
    └ <function _delete_data at 0x7f8c4e233b70>
> File "/data/projects/standalone-fate-master-1.5.0/python/wjc/venv/lib/python3.6/site-packages/fate_test/scripts/_utils.py", line 139, in _delete_data
    clients[data.role_str].delete_data(data)
    │       │    │                     └ <fate_test._parser.Data object at 0x7f8c4e1d9710>
    │       │    └ 'host_0'
    │       └ <fate_test._parser.Data object at 0x7f8c4e1d9710>
    └ <fate_test._client.Clients object at 0x7f8c86a91630>
  File "/data/projects/standalone-fate-master-1.5.0/python/wjc/venv/lib/python3.6/site-packages/fate_test/_flow_client.py", line 58, in delete_data
    raise RuntimeError(f"delete data failed") from e

RuntimeError: delete data failed
